Workbook

Sheet NordDRG-LLM-Benchmark 20250820
B2: NordDRG AI Benchmark for LLMs
B4: Dataset | C4: Format | D4: Description
B5: Definition Tables | C5: XLSX | D5: NordDRG Definition Tables
B6: PDF Instructions | C6: PDF | D6: NordDRG PDF Instructions
B7: Definition Tables: Part of the tables FI | C7: XLSX | D7: NordDRG Definition Tables: Finnish DRG List with Finnish Descriptions only
B8: Definition Tables: Part of the tables FI-EN | C8: XLSX | D8: NordDRG Definition Tables: Finnish DRG List with Finnish and English descriptions of groups
B9: Questions | C9: XLSX | D9: NordDRG Questions and Right answers
B11: Dataset configurations | C11: Type | D11: =D4 -> Description
B12: =B5 -> Definition Tables | C12: Tables | D12: =D5 -> NordDRG Definition Tables
B13: =B5&" + "&B6 -> Definition Tables + PDF Instructions | C13: Tables+Instructions | D13: Definition tables and PDF descriptions
B14: =B7 -> Definition Tables: Part of the tables FI | C14: PortionOfTables | D14: =D7 -> NordDRG Definition Tables: Finnish DRG List with Finnish Descriptions only
B15: =B8 -> Definition Tables: Part of the tables FI-EN | C15: PortionOfTables | D15: =D8 -> NordDRG Definition Tables: Finnish DRG List with Finnish and English descriptions of groups
B17: Initial prompt for the LLM | D17: Read attached tables and PDF documents. Answer following questions only based on the documents provided for you in this context. You are not allowed to use web searches.
B19: NordDRG AI Logic Benchmark
B20: Uses definition table version | C20: Combined2024PL
A22: ID | B22: Use Case Category | C22: Difficulty | D22: CaseMix Question | E22: Right answer | F22: Comment
A23: Logic-1 | B23: Understanding NordDRG Definition Tables | C23: Easy | D23: Could you list all DRG groups in all NordDRG national version where the main treatment during the hospital visit was related to appendectomy? Please provide a list of drg_comb codes without duplicates. | E23: 166C, 166N,167N,167X,167O | F23: Code: drg_comb
A24: Logic-2 | B24: Understanding NordDRG Definition Tables | C24: Easy | D24: Could you list all DRG groups in the Finnish DRG version where the main treatment during the hospital visit was related to appendectomy? Please provide a list of drg_comb codes without duplicates. | E24: 166N,167X,167O | F24: Code: drg_comb
A25: Logic-3 | B25: Medical Terms in Local Minority Language | C25: Easy | D25: Could you list DRG groups where main treatment during the hospital visit might be related to Finnish word umpilisäke in Finnish DRG version? | E25: 166N,167X,167O | F25: Code: drg_comb
A26: Logic-4 | B26: Understanding NordDRG Definition Tables | C26: Medium | D26: How would you list all NordDRG groups across all national versions where a maternal delivery (vaginal or cesarean) occurs during an inpatient, outpatient, or primary-care episode of care—excluding the 'left-over' groups (468, 470, 477, Z75R, Z76R)? | E26: 370B, 370C, 370M, 370X, 371O, 371X, 372B, 372C, 372M, 372X, 373O, 373X, 374X, 375X, P05S, P05T | F26: Code: drg_comb
A27: Logic-5 | B27: Medical Terms in Local Minority Language | C27: Medium | D27: Could you list DRG groups where the main treatment during the hospital visit might be related to Finnish word umpilisäke in All DRG versions from all countries? Use the drg_comb column codes and combine them into one list | E27: 166C, 166N,167N,167X,167O | F27: Code: drg_comb
A28: Logic-6 | B28: Surgical Procedure Logic | C28: Medium | D28: For DRG 166N which procedure codes have the connection through the procedure property? Use NCSP plus codes in your answer | E28: JESA00, JESA01, JESA10, JESW96, JESW97 | F28: Code: NCSP+
A29: Logic-7 | B29: Connection between Definition Tables | C29: Medium | D29: Which diagnosis codes are linked to DRG 166N through diagnosis properties in All DRG versions from all countries? | E29: C1810,K3520 | F29: Code: ICD+
A30: Logic-8 | B30: Diagnosis Properties | C30: Medium | D30: Which diagnosis (ICD) codes are connected to diagnosis property 14X03? | E30: O6010, O6020, O6030, O6230, O6300, O6310, O6320, O6390, O6800, O6810, O6820, O6830, O6880, O6890, O7100, O7110, O7550, O7570, O8000, O8010, O8080, O8090, O8100, O8110, O8120, O8130, O8140, O8150, O8300, O8310, O8320, O8330, O8340, O8380, O8390, O8400, O8410, O8420, O8480, O8490, Z3700, Z3710, Z3720, Z3730, Z3740, Z3750, Z3760, Z3770, Z3790 | F30: List of 49 codes starting with O6010 and ending with Z3790
A31: Logic-9 | B31: Connection between Definition Tables | C31: Medium | D31: Which diagnosis categories and properties are listed in drg_logic for DRG group 372C? | E31: 14X03, 14X11, 14X13, 00X10
A32: Logic-10 | B32: Understanding NordDRG Definition Tables | C32: Medium | D32: How would you list all NordDRG groups across every national version where a maternal delivery (vaginal or cesarean) occurs during an inpatient or outpatient hospital episode of care - excluding primary-care delivery DRGs and the “left-over” groups (468*, 470*, 477*, Z75R, Z76R)? | E32: 370B, 370C, 370M, 370X, 371O, 371X, 372B, 372C, 372M, 372X, 373O, 373X, 374X, 375X
A33: Logic-11 | B33: Understanding NordDRG Definition Tables | C33: Medium | D33: How would you list all NordDRG groups across all national versions for newborn episodes of care (MDC 15) during an inpatient, outpatient, or primary-care setting—excluding the 'left-over' groups (468, 470, 477, Z75R, Z76R)? | E33: 385A, 385B, 385C, 386N, 387N, 388A, 388B, 388C, 389A, 389B, 389C, 390X, 391O, 391X, 815O, 858T, 858V, 858W, 915O, 970Q, Q69L, Q93R, Q97R, Q99R, Q99U, Q99W
A34: Logic-12 | B34: Understanding NordDRG Complication Logic | C34: Medium | D34: For a case with principal diagnosis A5990 and secondary diagnosis G8000 (Spastic cerebral palsy),is the secondary counted as a valid complication? | E34: No
A35: Logic-13 | B35: Understanding NordDRG Complication Logic | C35: Medium | D35: For a case with principal diagnosis B3710 and secondary diagnosis J1590 (Bacterial pneumonia, unspecified),is the secondary counted as a valid complication? | E35: Yes
B37: NordDRG AI Grouper Benchmark
B38: Uses definition table version | C38: NordDRG_FIN2026PL0
A40: =A22 -> ID | B40: =B22 -> Use Case Category | C40: =C22 -> Difficulty | D40: =D22 -> CaseMix Question | E40: =E22 -> Right answer
A41: Grouper-1 | B41: Emulating DRG grouper | C41: Hard | D41: Select the test case with ID 49483 from your tables. Under the Finnish (Finland) NordDRG grouper logic, which DRG group would this case be assigned to? What is the drg_logic.id of the corresponding row? | E41: drg_nat=470E, drg_logic_id=000D004100
A42: Grouper-2 | B42: Emulating DRG grouper | C42: Hard | D42: Select the test case with ID 50184 from your tables. Under the Finnish (Finland) NordDRG grouper logic, which DRG group would this case be assigned to? What is the drg_logic.id of the corresponding row? | E42: drg_nat=373, drg_logic_id=400D783000
A43: Grouper-3 | B43: Emulating DRG grouper | C43: Hard | D43: Select the test case with ID 50166 from your tables. Under the Finnish (Finland) NordDRG grouper logic, which DRG group would this case be assigned to? What is the drg_logic.id of the corresponding row? | E43: drg_nat=704O, drg_logic_id=106D120110
A44: Grouper-4 | B44: Emulating DRG grouper | C44: Hard | D44: Select the test case with ID 50629 from your tables. Under the Finnish (Finland) NordDRG grouper logic, which DRG group would this case be assigned to? What is the drg_logic.id of the corresponding row? | E44: drg_nat=468, drg_logic_id=499D000100
A45: Grouper-5 | B45: Emulating DRG grouper | C45: Hard | D45: Select the test case with ID 66704 from your tables. Under the Finnish (Finland) NordDRG grouper logic, which DRG group would this case be assigned to? What is the drg_logic.id of the corresponding row? | E45: drg_nat=911O, drg_logic_id=111D169960
A46: Grouper-6 | B46: Emulating DRG grouper | C46: Hard | D46: Select the test case with ID 53273 from your tables. Under the Finnish (Finland) NordDRG grouper logic, which DRG group would this case be assigned to? What is the drg_logic.id of the corresponding row? | E46: drg_nat=384B, drg_logic_id=414D3710002
A47: Grouper-7 | B47: Emulating DRG grouper | C47: Hard | D47: Select the test case with ID 49486 from your tables. Under the Finnish (Finland) NordDRG grouper logic, which DRG group would this case be assigned to? What is the drg_logic.id of the corresponding row? | E47: drg_nat=388A, drg_logic_id=015D816140
A48: Grouper-8 | B48: Emulating DRG grouper | C48: Hard | D48: Select the test case with ID 49571 from your tables. Under the Finnish (Finland) NordDRG grouper logic, which DRG group would this case be assigned to? What is the drg_logic.id of the corresponding row? | E48: drg_nat=004, drg_logic_id=401D041000
...

Sheet Questions
B2: ='NordDRG-LLM-Benchmark 20250820'!A22 -> ID | C2: Question
B3: ='NordDRG-LLM-Benchmark 20250820'!A23 -> Logic-1 | C3: ='NordDRG-LLM-Benchmark 20250820'!D23 -> Could you list all DRG groups in all NordDRG national version where the main treatment during the hospital visit was related to appendectomy? Please provide a list of drg_comb codes without duplicates.
B4: ='NordDRG-LLM-Benchmark 20250820'!A24 -> Logic-2 | C4: ='NordDRG-LLM-Benchmark 20250820'!D24 -> Could you list all DRG groups in the Finnish DRG version where the main treatment during the hospital visit was related to appendectomy? Please provide a list of drg_comb codes without duplicates.
B5: ='NordDRG-LLM-Benchmark 20250820'!A25 -> Logic-3 | C5: ='NordDRG-LLM-Benchmark 20250820'!D25 -> Could you list DRG groups where main treatment during the hospital visit might be related to Finnish word umpilisäke in Finnish DRG version?
B6: ='NordDRG-LLM-Benchmark 20250820'!A26 -> Logic-4 | C6: ='NordDRG-LLM-Benchmark 20250820'!D26 -> How would you list all NordDRG groups across all national versions where a maternal delivery (vaginal or cesarean) occurs during an inpatient, outpatient, or primary-care episode of care—excluding the 'left-over' groups (468, 470, 477, Z75R, Z76R)?
B7: ='NordDRG-LLM-Benchmark 20250820'!A27 -> Logic-5 | C7: ='NordDRG-LLM-Benchmark 20250820'!D27 -> Could you list DRG groups where the main treatment during the hospital visit might be related to Finnish word umpilisäke in All DRG versions from all countries? Use the drg_comb column codes and combine them into one list
B8: ='NordDRG-LLM-Benchmark 20250820'!A28 -> Logic-6 | C8: ='NordDRG-LLM-Benchmark 20250820'!D28 -> For DRG 166N which procedure codes have the connection through the procedure property? Use NCSP plus codes in your answer
B9: ='NordDRG-LLM-Benchmark 20250820'!A29 -> Logic-7 | C9: ='NordDRG-LLM-Benchmark 20250820'!D29 -> Which diagnosis codes are linked to DRG 166N through diagnosis properties in All DRG versions from all countries?
B10: ='NordDRG-LLM-Benchmark 20250820'!A30 -> Logic-8 | C10: ='NordDRG-LLM-Benchmark 20250820'!D30 -> Which diagnosis (ICD) codes are connected to diagnosis property 14X03?
B11: ='NordDRG-LLM-Benchmark 20250820'!A31 -> Logic-9 | C11: ='NordDRG-LLM-Benchmark 20250820'!D31 -> Which diagnosis categories and properties are listed in drg_logic for DRG group 372C?
B12: ='NordDRG-LLM-Benchmark 20250820'!A32 -> Logic-10 | C12: ='NordDRG-LLM-Benchmark 20250820'!D32 -> How would you list all NordDRG groups across every national version where a maternal delivery (vaginal or cesarean) occurs during an inpatient or outpatient hospital episode of care - excluding primary-care delivery DRGs and the “left-over” groups (468*, 470*, 477*, Z75R, Z76R)?
B13: ='NordDRG-LLM-Benchmark 20250820'!A33 -> Logic-11 | C13: ='NordDRG-LLM-Benchmark 20250820'!D33 -> How would you list all NordDRG groups across all national versions for newborn episodes of care (MDC 15) during an inpatient, outpatient, or primary-care setting—excluding the 'left-over' groups (468, 470, 477, Z75R, Z76R)?
B14: ='NordDRG-LLM-Benchmark 20250820'!A34 -> Logic-12 | C14: ='NordDRG-LLM-Benchmark 20250820'!D34 -> For a case with principal diagnosis A5990 and secondary diagnosis G8000 (Spastic cerebral palsy),is the secondary counted as a valid complication?
B15: ='NordDRG-LLM-Benchmark 20250820'!A35 -> Logic-13 | C15: ='NordDRG-LLM-Benchmark 20250820'!D35 -> For a case with principal diagnosis B3710 and secondary diagnosis J1590 (Bacterial pneumonia, unspecified),is the secondary counted as a valid complication?
B17: ='NordDRG-LLM-Benchmark 20250820'!A40 -> ID | C17: Question
B18: ='NordDRG-LLM-Benchmark 20250820'!A41 -> Grouper-1 | C18: ='NordDRG-LLM-Benchmark 20250820'!D41 -> Select the test case with ID 49483 from your tables. Under the Finnish (Finland) NordDRG grouper logic, which DRG group would this case be assigned to? What is the drg_logic.id of the corresponding row?
B19: ='NordDRG-LLM-Benchmark 20250820'!A42 -> Grouper-2 | C19: ='NordDRG-LLM-Benchmark 20250820'!D42 -> Select the test case with ID 50184 from your tables. Under the Finnish (Finland) NordDRG grouper logic, which DRG group would this case be assigned to? What is the drg_logic.id of the corresponding row?
B20: ='NordDRG-LLM-Benchmark 20250820'!A43 -> Grouper-3 | C20: ='NordDRG-LLM-Benchmark 20250820'!D43 -> Select the test case with ID 50166 from your tables. Under the Finnish (Finland) NordDRG grouper logic, which DRG group would this case be assigned to? What is the drg_logic.id of the corresponding row?
B21: ='NordDRG-LLM-Benchmark 20250820'!A44 -> Grouper-4 | C21: ='NordDRG-LLM-Benchmark 20250820'!D44 -> Select the test case with ID 50629 from your tables. Under the Finnish (Finland) NordDRG grouper logic, which DRG group would this case be assigned to? What is the drg_logic.id of the corresponding row?
B22: ='NordDRG-LLM-Benchmark 20250820'!A45 -> Grouper-5 | C22: ='NordDRG-LLM-Benchmark 20250820'!D45 -> Select the test case with ID 66704 from your tables. Under the Finnish (Finland) NordDRG grouper logic, which DRG group would this case be assigned to? What is the drg_logic.id of the corresponding row?
B23: ='NordDRG-LLM-Benchmark 20250820'!A46 -> Grouper-6 | C23: ='NordDRG-LLM-Benchmark 20250820'!D46 -> Select the test case with ID 53273 from your tables. Under the Finnish (Finland) NordDRG grouper logic, which DRG group would this case be assigned to? What is the drg_logic.id of the corresponding row?
B24: ='NordDRG-LLM-Benchmark 20250820'!A47 -> Grouper-7 | C24: ='NordDRG-LLM-Benchmark 20250820'!D47 -> Select the test case with ID 49486 from your tables. Under the Finnish (Finland) NordDRG grouper logic, which DRG group would this case be assigned to? What is the drg_logic.id of the corresponding row?
B25: ='NordDRG-LLM-Benchmark 20250820'!A48 -> Grouper-8 | C25: ='NordDRG-LLM-Benchmark 20250820'!D48 -> Select the test case with ID 49571 from your tables. Under the Finnish (Finland) NordDRG grouper logic, which DRG group would this case be assigned to? What is the drg_logic.id of the corresponding row?
B26: ='NordDRG-LLM-Benchmark 20250820'!A49 -> Grouper-9 | C26: ='NordDRG-LLM-Benchmark 20250820'!D49 -> Select the test case with ID 49597 from your tables. Under the Finnish (Finland) NordDRG grouper logic, which DRG group would this case be assigned to? What is the drg_logic.id of the corresponding row?
B27: ='NordDRG-LLM-Benchmark 20250820'!A50 -> Grouper-10 | C27: ='NordDRG-LLM-Benchmark 20250820'!D50 -> Select the test case with ID 49606 from your tables. Under the Finnish (Finland) NordDRG grouper logic, which DRG group would this case be assigned to? What is the drg_logic.id of the corresponding row?
B28: ='NordDRG-LLM-Benchmark 20250820'!A51 -> Grouper-11 | C28: ='NordDRG-LLM-Benchmark 20250820'!D51 -> Select the test case with ID 49968 from your tables. Under the Finnish (Finland) NordDRG grouper logic, which DRG group would this case be assigned to? What is the drg_logic.id of the corresponding row?
B29: ='NordDRG-LLM-Benchmark 20250820'!A52 -> Grouper-12 | C29: ='NordDRG-LLM-Benchmark 20250820'!D52 -> Select the test case with ID 54051 from your tables. Under the Finnish (Finland) NordDRG grouper logic, which DRG group would this case be assigned to? What is the drg_logic.id of the corresponding row?
B30: ='NordDRG-LLM-Benchmark 20250820'!A53 -> Grouper-13 | C30: ='NordDRG-LLM-Benchmark 20250820'!D53 -> Select the test case with ID 54096 from your tables. Under the Finnish (Finland) NordDRG grouper logic, which DRG group would this case be assigned to? What is the drg_logic.id of the corresponding row?

Sheet Answers
B2: ='NordDRG-LLM-Benchmark 20250820'!A22 -> ID | C2: ='NordDRG-LLM-Benchmark 20250820'!E22 -> Right answer
B3: ='NordDRG-LLM-Benchmark 20250820'!A23 -> Logic-1 | C3: ='NordDRG-LLM-Benchmark 20250820'!E23 -> 166C, 166N,167N,167X,167O
B4: ='NordDRG-LLM-Benchmark 20250820'!A24 -> Logic-2 | C4: ='NordDRG-LLM-Benchmark 20250820'!E24 -> 166N,167X,167O
B5: ='NordDRG-LLM-Benchmark 20250820'!A25 -> Logic-3 | C5: ='NordDRG-LLM-Benchmark 20250820'!E25 -> 166N,167X,167O
B6: ='NordDRG-LLM-Benchmark 20250820'!A26 -> Logic-4 | C6: ='NordDRG-LLM-Benchmark 20250820'!E26 -> 370B, 370C, 370M, 370X, 371O, 371X, 372B, 372C, 372M, 372X, 373O, 373X, 374X, 375X, P05S, P05T
B7: ='NordDRG-LLM-Benchmark 20250820'!A27 -> Logic-5 | C7: ='NordDRG-LLM-Benchmark 20250820'!E27 -> 166C, 166N,167N,167X,167O
B8: ='NordDRG-LLM-Benchmark 20250820'!A28 -> Logic-6 | C8: ='NordDRG-LLM-Benchmark 20250820'!E28 -> JESA00, JESA01, JESA10, JESW96, JESW97
B9: ='NordDRG-LLM-Benchmark 20250820'!A29 -> Logic-7 | C9: ='NordDRG-LLM-Benchmark 20250820'!E29 -> C1810,K3520
B10: ='NordDRG-LLM-Benchmark 20250820'!A30 -> Logic-8 | C10: ='NordDRG-LLM-Benchmark 20250820'!E30 -> O6010, O6020, O6030, O6230, O6300, O6310, O6320, O6390, O6800, O6810, O6820, O6830, O6880, O6890, O7100, O7110, O7550, O7570, O8000, O8010, O8080, O8090, O8100, O8110, O8120, O8130, O8140, O8150, O8300, O8310, O8320, O8330, O8340, O8380, O8390, O8400, O8410, O8420, O8480, O8490, Z3700, Z3710, Z3720, Z3730, Z3740, Z3750, Z3760, Z3770, Z3790
B11: ='NordDRG-LLM-Benchmark 20250820'!A31 -> Logic-9 | C11: ='NordDRG-LLM-Benchmark 20250820'!E31 -> 14X03, 14X11, 14X13, 00X10
B12: ='NordDRG-LLM-Benchmark 20250820'!A32 -> Logic-10 | C12: ='NordDRG-LLM-Benchmark 20250820'!E32 -> 370B, 370C, 370M, 370X, 371O, 371X, 372B, 372C, 372M, 372X, 373O, 373X, 374X, 375X
B13: ='NordDRG-LLM-Benchmark 20250820'!A33 -> Logic-11 | C13: ='NordDRG-LLM-Benchmark 20250820'!E33 -> 385A, 385B, 385C, 386N, 387N, 388A, 388B, 388C, 389A, 389B, 389C, 390X, 391O, 391X, 815O, 858T, 858V, 858W, 915O, 970Q, Q69L, Q93R, Q97R, Q99R, Q99U, Q99W
... B15: ='NordDRG-LLM-Benchmark 20250820'!A35 -> Logic-13 | C15: ='NordDRG-LLM-Benchmark 20250820'!E35 -> Yes
B17: ='NordDRG-LLM-Benchmark 20250820'!A40 -> ID | C17: ='NordDRG-LLM-Benchmark 20250820'!E40 -> Right answer
B18: ='NordDRG-LLM-Benchmark 20250820'!A41 -> Grouper-1 | C18: ='NordDRG-LLM-Benchmark 20250820'!E41 -> drg_nat=470E, drg_logic_id=000D004100
B19: ='NordDRG-LLM-Benchmark 20250820'!A42 -> Grouper-2 | C19: ='NordDRG-LLM-Benchmark 20250820'!E42 -> drg_nat=373, drg_logic_id=400D783000
B20: ='NordDRG-LLM-Benchmark 20250820'!A43 -> Grouper-3 | C20: ='NordDRG-LLM-Benchmark 20250820'!E43 -> drg_nat=704O, drg_logic_id=106D120110
B21: ='NordDRG-LLM-Benchmark 20250820'!A44 -> Grouper-4 | C21: ='NordDRG-LLM-Benchmark 20250820'!E44 -> drg_nat=468, drg_logic_id=499D000100
B22: ='NordDRG-LLM-Benchmark 20250820'!A45 -> Grouper-5 | C22: ='NordDRG-LLM-Benchmark 20250820'!E45 -> drg_nat=911O, drg_logic_id=111D169960
B23: ='NordDRG-LLM-Benchmark 20250820'!A46 -> Grouper-6 | C23: ='NordDRG-LLM-Benchmark 20250820'!E46 -> drg_nat=384B, drg_logic_id=414D3710002
B24: ='NordDRG-LLM-Benchmark 20250820'!A47 -> Grouper-7 | C24: ='NordDRG-LLM-Benchmark 20250820'!E47 -> drg_nat=388A, drg_logic_id=015D816140
B25: ='NordDRG-LLM-Benchmark 20250820'!A48 -> Grouper-8 | C25: ='NordDRG-LLM-Benchmark 20250820'!E48 -> drg_nat=004, drg_logic_id=401D041000
B26: ='NordDRG-LLM-Benchmark 20250820'!A49 -> Grouper-9 | C26: ='NordDRG-LLM-Benchmark 20250820'!E49 -> drg_nat=477, drg_logic_id=414D022100
B27: ='NordDRG-LLM-Benchmark 20250820'!A50 -> Grouper-10 | C27: ='NordDRG-LLM-Benchmark 20250820'!E50 -> drg_nat=901O, drg_logic_id=101D089890
B28: ='NordDRG-LLM-Benchmark 20250820'!A51 -> Grouper-11 | C28: ='NordDRG-LLM-Benchmark 20250820'!E51 -> drg_nat=125O, drg_logic_id=105D230000
... B30: ='NordDRG-LLM-Benchmark 20250820'!A53 -> Grouper-13 | C30: ='NordDRG-LLM-Benchmark 20250820'!E53 -> drg_nat=291M, drg_logic_id=410D110101
